<?xml version="1.0" ?>
<robot name="jetacker">
  <material name="black">
    <color rgba="0.1 0.1 0.1 1.0"/>
  </material>
  <material name="blue">
    <color rgba="0.0 0.0 0.8 1.0"/>
  </material>
  <material name="green">
    <color rgba="0.4 0.9 0.4 1.0"/>
  </material>
  <material name="gray">
    <color rgba="0.7 0.7 0.7 1.0"/>
  </material>
  <material name="darkgray">
    <color rgba="0.3 0.3 0.3 1.0"/>
  </material>
  <material name="red">
    <color rgba="0.8 0.0 0.0 1.0"/>
  </material>
  <material name="white">
    <color rgba="1.0 1.0 1.0 1.0"/>
  </material>
  <material name="yellow">
    <color rgba="0.8 0.8 0.0 1.0"/>
  </material>
  <link name="base_footprint"/>
  <joint name="base_footprint_joint" type="fixed">
    <parent link="base_footprint"/>
    <child link="base_link"/>
    <origin rpy="0 0 0" xyz="0 0 -0.0003"/>
  </joint>
  <link name="base_link">
    <inertial>
      <mass value="1.6"/>
      <inertia ixx="0.005530133333333334" ixy="0" ixz="0" iyy="0.013798933333333332" iyz="0" izz="0.015095466666666666"/>
    </inertial>
    <visual>
      <origin rpy="-1.5707963267948966 0 0" xyz="0 0 0"/>
      <geometry>
        <mesh filename="package://jetacker_description/meshes/base_link.stl"/>
      </geometry>
      <material name="black"/>
    </visual>
    <collision>
      <origin rpy="0 0 0" xyz="-0.004 0 0.085"/>
      <geometry>
        <box size="0.296 0.16 0.126"/>
      </geometry>
    </collision>
  </link>
  <link name="back_shell_link">
    <inertial>
      <mass value="1.6"/>
      <inertia ixx="0.005056666666666668" ixy="0" ixz="0" iyy="0.007656666666666667" iyz="0" izz="0.010306666666666667"/>
    </inertial>
    <visual>
      <origin rpy="-1.5707963267948966 0 0" xyz="0 0 0"/>
      <geometry>
        <mesh filename="package://jetacker_description/meshes/back_shell_link.stl"/>
      </geometry>
      <material name="green"/>
    </visual>
    <collision>
      <origin rpy="0 0 0" xyz="-0.04 0 0.1955"/>
      <geometry>
        <box size="0.22 0.17 0.095"/>
      </geometry>
    </collision>
  </link>
  <joint name="back_shell_joint" type="fixed">
    <origin rpy="0 0 0" xyz="0 0 0"/>
    <parent link="base_link"/>
    <child link="back_shell_link"/>
  </joint>
  <link name="turret_link">
    <inertial>
      <origin rpy="0 0 0" xyz="0.000273458158848059 4.49697391709507E-08 0.0127682239974202"/>
      <mass value="0.0117617552923888"/>
      <inertia ixx="2.42304907313034E-06" ixy="8.36427578709212E-13" ixz="-4.88815706874446E-08" iyy="2.24167366920736E-06" iyz="2.4783598093895E-12" izz="3.78066563706159E-06"/>
    </inertial>
    <visual>
      <origin rpy="-1.5707963267948966 0 0" xyz="0 0 0"/>
      <geometry>
        <mesh filename="package://jetacker_description/meshes/turret_link.stl"/>
      </geometry>
      <material name="black"/>
    </visual>
  </link>
  <joint name="turret_joint" type="revolute">
    <origin rpy="0 0 0" xyz="0.0313 0.0007 0.1616"/>
    <parent link="base_link"/>
    <child link="turret_link"/>
    <axis xyz="0 0 1"/>
    <limit effort="1000" lower="-2.09" upper="2.09" velocity="10"/>
  </joint>
  <link name="depth_cam_link">
    <inertial>
      <origin rpy="0 0 0" xyz="-0.00267477609208174 -1.63263137193841E-05 -0.00522210299748882"/>
      <mass value="0.22552781639362"/>
      <inertia ixx="0.000408522155796754" ixy="-7.65921501012663E-09" ixz="1.66771046033071E-07" iyy="4.81468336120099E-05" iyz="-5.69880969191004E-09" izz="0.000428962116485588"/>
    </inertial>
    <visual>
      <origin rpy="-1.5707963267948966 0 0" xyz="0 0 0"/>
      <geometry>
        <mesh filename="package://jetacker_description/meshes/depth_cam_link.stl"/>
      </geometry>
      <material name="black"/>
    </visual>
  </link>
  <joint name="depth_cam_joint" type="fixed">
    <origin rpy="0 0 0" xyz="0.0057651 0.00025 0.057913"/>
    <parent link="turret_link"/>
    <child link="depth_cam_link"/>
  </joint>
  <link name="lidar_link">
    <inertial>
      <origin rpy="0 0 0" xyz="-0.00221931680115031 0.000376419599582719 -0.0173018800523995"/>
      <mass value="0.0438457545362112"/>
      <inertia ixx="1.59958556469832E-05" ixy="4.53029353441676E-08" ixz="2.33892337631863E-07" iyy="2.04183700013467E-05" iyz="-1.10000396493279E-08" izz="3.50483610398295E-05"/>
    </inertial>
    <visual>
      <origin rpy="-1.5707963267948966 0 0" xyz="0 0 0"/>
      <geometry>
        <mesh filename="package://jetacker_description/meshes/lidar_link.stl"/>
      </geometry>
      <material name="black"/>
    </visual>
  </link>
  <joint name="lidar_joint" type="fixed">
    <origin rpy="0 0 0" xyz="0.104 0.0007 0.134"/>
    <parent link="base_link"/>
    <child link="lidar_link"/>
  </joint>
  <link name="lidar_frame"/>
  <joint name="lidar_frame_joint" type="fixed">
    <origin rpy="0 0 0" xyz="0 0 0"/>
    <parent link="lidar_link"/>
    <child link="lidar_frame"/>
  </joint>
  <link name="lidar_sim_frame"/>
  <joint name="lidar_sim_frame_joint" type="fixed">
    <origin rpy="0 0 3.141592653589793" xyz="0 0 0"/>
    <parent link="lidar_link"/>
    <child link="lidar_sim_frame"/>
  </joint>
  <link name="tof_rear_left_link">
    <visual>
      <geometry>
        <sphere radius="0.01"/>
      </geometry>
      <material name="red"/>
    </visual>
  </link>
  <joint name="tof_rear_left_joint" type="fixed">
    <origin rpy="0 0 2.8797932657906435" xyz="-0.15 0.08 0.08"/>
    <parent link="base_link"/>
    <child link="tof_rear_left_link"/>
  </joint>
  <link name="tof_rear_right_link">
    <visual>
      <geometry>
        <sphere radius="0.01"/>
      </geometry>
      <material name="red"/>
    </visual>
  </link>
  <joint name="tof_rear_right_joint" type="fixed">
    <origin rpy="0 0 3.4033920413889427" xyz="-0.15 -0.08 0.08"/>
    <parent link="base_link"/>
    <child link="tof_rear_right_link"/>
  </joint>
  <link name="imu_link"/>
  <joint name="imu_joint" type="fixed">
    <origin rpy="0 0 -1.5707963267948966" xyz="0 0 0.1116"/>
    <parent link="base_link"/>
    <child link="imu_link"/>
  </joint>
  <link name="front_steering_link">
    <inertial>
      <mass value="0.001"/>
      <inertia ixx="1e-05" ixy="0.0" ixz="0.0" iyy="1e-05" iyz="0.0" izz="1e-05"/>
    </inertial>
  </link>
  <joint name="front_steering_joint" type="revolute">
    <parent link="base_link"/>
    <child link="front_steering_link"/>
    <origin rpy="0 0 0" xyz="0.107 0 0.05"/>
    <axis xyz="0 0 1"/>
    <limit effort="10" lower="-0.4887" upper="0.4887" velocity="1"/>
  </joint>
  <link name="front_left_wheel_steering">
    <inertial>
      <mass value="0.01"/>
      <inertia ixx="0.0001" ixy="0.0" ixz="0.0" iyy="0.0001" iyz="0.0" izz="0.0001"/>
    </inertial>
  </link>
  <joint name="front_left_wheel_steering_joint" type="revolute">
    <parent link="base_link"/>
    <child link="front_left_wheel_steering"/>
    <origin rpy="0 0 0" xyz="0.107 0.091 0.05"/>
    <axis xyz="0 0 1"/>
    <limit effort="10" lower="-0.4887" upper="0.4887" velocity="1"/>
    <mimic joint="front_steering_joint" multiplier="1.0" offset="0.0"/>
  </joint>
  <link name="front_left_wheel">
    <inertial>
      <mass value="0.1"/>
      <inertia ixx="7.517500000000001e-05" ixy="0" ixz="0" iyy="7.517500000000001e-05" iyz="0" izz="0.00012500000000000003"/>
    </inertial>
    <visual>
      <origin rpy="-1.5707963267948966 0 0" xyz="0 0 0"/>
      <geometry>
        <mesh filename="package://jetacker_description/meshes/wheel_left_front.stl"/>
      </geometry>
      <material name="black"/>
    </visual>
    <collision>
      <origin rpy="1.5707963267948966 0 0" xyz="0 0.019 0"/>
      <geometry>
        <cylinder length="0.039" radius="0.05"/>
      </geometry>
    </collision>
  </link>
  <joint name="front_left_wheel_joint" type="continuous">
    <parent link="front_left_wheel_steering"/>
    <child link="front_left_wheel"/>
    <origin rpy="0 0 0" xyz="0 0 0"/>
    <axis xyz="0 1 0"/>
  </joint>
  <link name="front_right_wheel_steering">
    <inertial>
      <mass value="0.01"/>
      <inertia ixx="0.0001" ixy="0.0" ixz="0.0" iyy="0.0001" iyz="0.0" izz="0.0001"/>
    </inertial>
  </link>
  <joint name="front_right_wheel_steering_joint" type="revolute">
    <parent link="base_link"/>
    <child link="front_right_wheel_steering"/>
    <origin rpy="0 0 0" xyz="0.107 -0.091 0.05"/>
    <axis xyz="0 0 1"/>
    <limit effort="10" lower="-0.4887" upper="0.4887" velocity="1"/>
    <mimic joint="front_steering_joint" multiplier="1.0" offset="0.0"/>
  </joint>
  <link name="front_right_wheel">
    <inertial>
      <mass value="0.1"/>
      <inertia ixx="7.517500000000001e-05" ixy="0" ixz="0" iyy="7.517500000000001e-05" iyz="0" izz="0.00012500000000000003"/>
    </inertial>
    <visual>
      <origin rpy="-1.5707963267948966 0 0" xyz="0 0 0"/>
      <geometry>
        <mesh filename="package://jetacker_description/meshes/wheel_right_front.stl"/>
      </geometry>
      <material name="black"/>
    </visual>
    <collision>
      <origin rpy="1.5707963267948966 0 0" xyz="0 -0.019 0"/>
      <geometry>
        <cylinder length="0.039" radius="0.05"/>
      </geometry>
    </collision>
  </link>
  <joint name="front_right_wheel_joint" type="continuous">
    <parent link="front_right_wheel_steering"/>
    <child link="front_right_wheel"/>
    <origin rpy="0 0 0" xyz="0 0 0"/>
    <axis xyz="0 1 0"/>
  </joint>
  <link name="rear_left_wheel">
    <inertial>
      <mass value="0.1"/>
      <inertia ixx="7.517500000000001e-05" ixy="0" ixz="0" iyy="7.517500000000001e-05" iyz="0" izz="0.00012500000000000003"/>
    </inertial>
    <visual>
      <origin rpy="-1.5707963267948966 0 0" xyz="0 0 0"/>
      <geometry>
        <mesh filename="package://jetacker_description/meshes/wheel_left_back.stl"/>
      </geometry>
      <material name="black"/>
    </visual>
    <collision>
      <origin rpy="1.5707963267948966 0 0" xyz="0 0.019 0"/>
      <geometry>
        <cylinder length="0.039" radius="0.05"/>
      </geometry>
    </collision>
  </link>
  <joint name="rear_left_wheel_joint" type="continuous">
    <parent link="base_link"/>
    <child link="rear_left_wheel"/>
    <origin rpy="0 0 0" xyz="-0.106 0.091 0.0503"/>
    <axis xyz="0 1 0"/>
  </joint>
  <link name="rear_right_wheel">
    <inertial>
      <mass value="0.1"/>
      <inertia ixx="7.517500000000001e-05" ixy="0" ixz="0" iyy="7.517500000000001e-05" iyz="0" izz="0.00012500000000000003"/>
    </inertial>
    <visual>
      <origin rpy="-1.5707963267948966 0 0" xyz="0 0 0"/>
      <geometry>
        <mesh filename="package://jetacker_description/meshes/wheel_right_back.stl"/>
      </geometry>
      <material name="black"/>
    </visual>
    <collision>
      <origin rpy="1.5707963267948966 0 0" xyz="0 -0.019 0"/>
      <geometry>
        <cylinder length="0.039" radius="0.05"/>
      </geometry>
    </collision>
  </link>
  <joint name="rear_right_wheel_joint" type="continuous">
    <parent link="base_link"/>
    <child link="rear_right_wheel"/>
    <origin rpy="0 0 0" xyz="-0.106 -0.091 0.0503"/>
    <axis xyz="0 -1 0"/>
  </joint>
  <ros2_control name="JetackerAckermannSystem" type="system">
    <hardware>
      <plugin>joint_state_topic_hardware_interface/JointStateTopicSystem</plugin>
      <param name="sum_wrapped_joint_states">false</param>
      <param name="trigger_joint_command_threshold">-1.0</param>
    </hardware>
    <joint name="front_steering_joint">
      <command_interface name="position"/>
      <state_interface name="position">
        <param name="initial_value">0.0</param>
      </state_interface>
      <state_interface name="velocity">
        <param name="initial_value">0.0</param>
      </state_interface>
    </joint>
    <joint name="rear_left_wheel_joint">
      <command_interface name="velocity"/>
      <state_interface name="position">
        <param name="initial_value">0.0</param>
      </state_interface>
      <state_interface name="velocity">
        <param name="initial_value">0.0</param>
      </state_interface>
    </joint>
    <joint name="rear_right_wheel_joint">
      <command_interface name="velocity"/>
      <state_interface name="position">
        <param name="initial_value">0.0</param>
      </state_interface>
      <state_interface name="velocity">
        <param name="initial_value">0.0</param>
      </state_interface>
    </joint>
    <joint name="turret_joint">
      <command_interface name="position"/>
      <state_interface name="position">
        <param name="initial_value">0.0</param>
      </state_interface>
      <state_interface name="velocity">
        <param name="initial_value">0.0</param>
      </state_interface>
    </joint>
  </ros2_control>
</robot>
